Workbook

Sheet Loan Information
A5: LOAN INFORMATION SHEET
A6: A. FOR DISCLOSURE STATEMENT
A7: 1 | B7: Name of Borrower | C7: JANET O. SARCEDA | E7: Employer | F7: DEP-ED | H7: Input Data
A8: 2 | B8: Address | C8: P-1A POB, BAROBO, SDS | H8: Input Data
A9: 3 | B9: Loan Approved | C9: 200000 | H9: Input Data
A10: 4 | B10: Interest Rate (Per Annum) | C10: 0.36 | H10: Input Data
A11: 5 | B11: Term of Loan (# of months) | C11: 12 | H11: Input Data
A12: 6 | B12: Service Charge | C12: 0.05 | H12: Input Data
A13: 7 | B13: Interest Not Deducted | C13: =C9*C10/12*C11 -> 72000 | H13: No Input Data
A14: 8 | B14: Certified Correct | C14: VELINA P. GAMUTAN | H14: Input Data
A15: 9 | B15: Position | C15: BOOKKEEPER | H15: Input Data
A16: 10 | B16: Kind of Loan | C16: SALARY LOAN | H16: Input Data
A17: 11 | B17: Mode of Payment | C17: MONTHLY | D17: Input Data | E17: 12 | H17: Input Data
A18: 12 | B18: Loan Manager | C18: ANNABELLE M. AMORA | H18: Input Data
A19: 13 | B19: Insurance Term(Max 12) | C19: 12 | H19: Input Data
A20: 14 | B20: Insurance Rate | C20: 1 | H20: Input Data
B21: Service Charge | C21: =C9*C12 -> 10000 | E21: DO NOT INPUT ANYTHING
B22: Insurance Premium | C22: =C9/1000*C19*C20 -> 2400 | E22: DO NOT INPUT ANYTHING
B23: Loan Security | C23: =C9*2% -> 4000 | E23: DO NOT INPUT ANYTHING
B24: Doc. Stamps | C24: =C9*1.5/200 -> 1500 | E24: DO NOT INPUT ANYTHING
B25: Notarial | C25: 100 | E25: DO NOT INPUT ANYTHING
B26: Amortization: | D26: Reference Data For Plan of Payment: | H26: No Input Data
B27: Principal | C27: =C9/E17 -> 16666.667 | D27: Daily | E27: =C11*21 -> 252 | F27: Weekly | G27: =C11*30/7 -> 51.428571 | H27: No Input Data
B28: Interest | C28: =C13/E17 -> 6000 | H28: No Input Data
B29: Savings (2%) | C29: =C27*2% -> 333.33333 | D29: Semi-monthly | E29: =C11*2 -> 24 | F29: Monthly | G29: =C11*1 -> 12 | H29: No Input Data
B30: TOTAL: | C30: =SUM(C27:C29) -> 23000 | H30: No Input Data
A31: B. FOR PROMISSORY NOTE
A32: 1 | B32: Co-Borrower 1 | C32: ELMA C. ANTONIANO | H32: Input Data
A33: 2 | B33: Co-Borrower 2 | C33: CYRENE M. RONQUILLO | H33: Input Data
A34: 3 | B34: Co-Borrower 1 Address | C34: P-4 POB, BAROBO, SDS | H34: Input Data
A35: 4 | B35: Co-Borrower Address | C35: P-1A POB, BAROBO, SDS | H35: Input Data
A36: 5 | B36: Term of Loan (# of days) | C36: 300 | H36: No Input Data
A37: 6 | B37: Amount of Loan (in words) | C37: FIFTY THOUSAND PESOS ONLY. | H37: Input Data
A38: 7 | B38: Int. Rate (word and #) | C38: TWENTY FOUR PERCENT (24%) | H38: Input Data
A39: 8 | B39: Payable Every (in words) | C39: MONTHLY | H39: Input Data
A40: 9 | B40: No. of Amortization | C40: =E17 -> 12 | H40: No Input Data
A41: 10 | B41: Penalty Per Month | C41: 0.05 | H41: Input Data
A42: 11 | B42: Sign in the presence of 1 | C42: KEYRIN B.LULAB | H42: Input Data
A43: 12 | B43: Sign in the presence of 2 | C43: ANNABELLE M. AMORA | H43: Input Data

Sheet Plan of Payment
G6: Date
B8: PLAN OF PAYMENT
A9: Name | C9: : | D9: ='Loan Information'!C7 -> JANET O. SARCEDA
A10: Address | C10: : | D10: ='Loan Information'!C8 -> P-1A POB, BAROBO, SDS
A11: Amount of Loan | C11: : | D11: ='Loan Information'!C9 -> 200000
A12: Kind of Loan | C12: : | D12: ='Loan Information'!C16 -> SALARY LOAN
B14: MODE OF PAYMENT
B15: ='Loan Information'!C17 -> MONTHLY
B17: Principal: | D17: ='Loan Information'!C27 -> 16666.667
B18: Interest: | D18: ='Loan Information'!C28 -> 6000
B19: Loan Security: | D19: ='Loan Information'!C29 -> 333.33333
B20: Total: | D20: ='Loan Information'!C30 -> 23000
B22: Starting: | F22: Ending:
A25: CONFORME: | F25: APPROVED:
B27: =D9 -> JANET O. SARCEDA | G27: ='Loan Information'!C18 -> ANNABELLE M. AMORA
B28: Signature of Borrower | G28: Loan Manager
G38: Date
B40: PLAN OF PAYMENT
A41: Name | C41: : | D41: =D9 -> JANET O. SARCEDA
A42: Address | C42: : | D42: =D10 -> P-1A POB, BAROBO, SDS
A43: Amount of Loan | C43: : | D43: =D11 -> 200000
A44: Kind of Loan | C44: : | D44: =D12 -> SALARY LOAN
B46: MODE OF PAYMENT
B47: =B15 -> MONTHLY
B49: Principal: | D49: =D17 -> 16666.667
B50: Interest: | D50: =D18 -> 6000
B51: Loan Security: | D51: =D19 -> 333.33333
B52: Total: | D52: =D20 -> 23000
B54: Starting: | F54: Ending:
A57: CONFORME: | F57: APPROVED:
B59: =D9 -> JANET O. SARCEDA | G59: =G27 -> ANNABELLE M. AMORA
B60: Signature of Borrower | G60: Loan Manager

Sheet Disclosure Statement
B4: DISCLOSURE STATEMENT ON LOAN/CREDIT TRANSACTION
D5: (As Required Under R.A. 3765 Truth In Lending Act)
A7: NAME OF BORROWER: | D7: ='Loan Information'!C7 -> JANET O. SARCEDA | L7: LOAN NUMBER
A8: ADDRESS: | C8: ='Loan Information'!C8 -> P-1A POB, BAROBO, SDS
A9: 1 | B9: LOAN GRANTED (Amount to be financed) | M9: (Php) | N9: ='Loan Information'!C9 -> 200000 | O9: ( A )
A10: 2 | B10: FINANCE CHARGES
J11: Not Deducted | L11: Deducted
J12: From | L12: From
J13: Proceeds of Loan
A14: a. | B14: Interest | D14: ='Loan Information'!C10 -> 0.36 | E14: % p.a. From | G14: To | I14: P | J14: ='Loan Information'!C13 -> 72000 | K14: P
B15: ( ) | C15: Single | E15: ( ) | F15: Monthly
B16: ( ) | C16: Compound | E16: ( ) | F16: Quarterly
B17: ( ) | C17: Semi-Annual | E17: ( ) | F17: Semi-Monthly
B18: ( ) | C18: Annual | E18: ( ) | F18: Lump-sum
A19: b. | B19: Premium Charges | E19: ( % )
A20: c. | B20: Commitment Fee
A21: d. | B21: Guarantee Fee
A22: e. | B22: Other Charges Incidental To The Extension of Credit
B23: (Specify) | D23: Service Charge At | F23: ='Loan Information'!C12 -> 0.05 | I23: P | K23: P | L23: ='Loan Information'!C21 -> 10000 | M23: P | N23: =L23+L14 -> 10000
A25: TOTAL FINANCE CHARGES | M25: P | N25: =N24+N23 -> 10000 | O25: ( B )
A27: 3 | B27: NON FINANCE CHARGES
B28: a. Insurance Premium | E28: P | F28: ='Loan Information'!C22 -> 2400
B29: b. Loan Security | E29: P | F29: ='Loan Information'!C23 -> 4000
B30: c. Documentary Stamps | E30: P | F30: ='Loan Information'!C24 -> 1500
B31: d. Notarial Fees | E31: P | F31: ='Loan Information'!C25 -> 100
B32: e. Others: | E32: P
A33: TOTAL NON FINANCE CHARGES | I33: P | L33: =F32+F31+F30+F29+F28 -> 8000 | M33: P | N33: =F32+F31+F30+F29+F28 -> 8000 | O33: ( C )
A34: 4 | B34: TOTAL DEDUCTIONS FROM PROCEEDS OF LOAN (B + C) | M34: P | N34: =N25+N33 -> 18000 | O34: ( D )
A35: 5 | B35: NET PROCEEDS OF LOAN (A LESS D) | M35: P | N35: =N9-N34 -> 182000 | O35: ( E )
A36: 6 | B36: PERCENTAGE OF FINANCE CHARGES TO TOTAL AMOUNT FINANCED
B37: (Computed in accordance with (Method of Computations in accordance with Sec. 2 (1) of CB Circular 158) | M37: %
A38: 7 | B38: EFFECTIVE INTEREST RATE | G38: % p.a.
A39: 8 | B39: SCHEDULE OF PAYMENT
B40: a. Single Payment Due On | E40: P
B41: b. Total Installment Payment | E41: P | F41: ='Loan Information'!C30 -> 23000 | G41: ='Loan Information'!C17 -> MONTHLY
B42: Payable in | D42: ='Loan Information'!C11 -> 12 | E42: months/quarter/years
A43: 9 | B43: COLLATERAL
B44: This loan is wholly/partly secured by:
B45: ( ) | D45: Check/s | E45: ( ) | F45: Chattels | G45: ( ) | H45: Government Securities
B46: ( ) | D46: Real Estate | E46: ( ) | F46: Unsecured
...

Sheet Promissory Note
D6: PROMISSORY NOTE
H8: Date Granted:
H9: Date Due:
H10: Amount: | I10: P | J10: ='Loan Information'!C9 -> 200000
A12: ='Loan Information'!C36 -> 300 | C12: days after date for value received, I/we promise to pay jointly and severally to the order of MICROFINANCE FOR RURAL
A13: DEVELOPMENT INC. the sum of | D13: ='Loan Information'!C37 -> FIFTY THOUSAND PESOS ONLY. | I13: P | J13: ='Loan Information'!C9 -> 200000
A14: Philippine Currency with an interest rate of | E14: ='Loan Information'!C38 -> TWENTY FOUR PERCENT (24%) | H14: per annum. Amortization/Installment payment of
A15: ='Loan Information'!C30 -> 23000 | C15: inclusive of interest every | E15: ='Loan Information'!C39 -> MONTHLY | F15: starting | I15: to | K15: for | L15: ='Loan Information'!C40 -> 12
A16: Amortization/Installment payment.
A18: In case I/we fail to pay this note on any of the amortization installments payments when due, I/we further agree to pay a penalty
A19: of 5% per month of any unpaid arrears starting from the date of default.
A21: In case of defect, fraud or misrepresentation in the application of this loan or violation of any of the terms of the loan evidenced by
A22: this note the entire outstanding balance shall immediately become due and demandable.
A24: I/We hereby agree and authorize MICROFINANCE FOR RURAL DEVELOPMENT INC. to encumber, assign or sell to any person or entity
A25: any right which may have under this note and/or any assignment, mortgage lien, pledge or other encumbrances constituted in favor
A26: of MICROFINANCE FOR RURAL DEVELOPMENT INC. pursuant to the provision of the loan agreement and this note if any. The consent
A27: herein granted is recognized and acknowledge by me/us as a waiver to all intents and purpose of whatever right I/We may have to
A28: notice of actual encumbrance are assignment.
A30: I/We further agree that in case of prepayment of the loan, MICROFINANCE FOR RURAL DEVELOPMENT INC. is not under any legal
A31: obligations to return the interest corresponding to the period from date of prepayment to the stipulated maturity date of the loan.
... A47: (SIGN OVER PRINTED NAME)
B50: ='Loan Information'!C7 -> JANET O. SARCEDA | E50: ='Loan Information'!C32 -> ELMA C. ANTONIANO | I50: ='Loan Information'!C33 -> CYRENE M. RONQUILLO
B51: Borrower | E51: Co-borrower 1 | I51: Co-borrower 2
A53: Address: | C53: ='Loan Information'!C8 -> P-1A POB, BAROBO, SDS | D53: Address: | E53: ='Loan Information'!C34 -> P-4 POB, BAROBO, SDS | H53: Address: | I53: ='Loan Information'!C35 -> P-1A POB, BAROBO, SDS
E55: Sign In The Presence Of
B58: ='Loan Information'!C42 -> KEYRIN B.LULAB | H58: ='Loan Information'!C43 -> ANNABELLE M. AMORA
